<?xml version="1.0" ?>
<!-- =================================================================================== -->
<!-- |    This document was autogenerated by xacro from src/kr2_robot_S00V0003M1805.xacro | -->
<!-- |    EDITING THIS FILE BY HAND IS NOT RECOMMENDED                                 | -->
<!-- =================================================================================== -->
<robot features="TIO" mechanical-revision="0" model="a1805" model-revision="250731-0" name="kr2_robot_a1805">
  <ruid>0</ruid>
  <!-- links -->
  <link name="base">
    <inertial>
      <origin rpy="0 0 0" xyz="0 0 0.1365"/>
      <mass value="8.2"/>
      <inertia ixx="0.003" ixy="0.0" ixz="0.0" iyy="0.003" iyz="0.0" izz="0.003"/>
    </inertial>
    <visual>
      <origin rpy="0 0 0" xyz="0 0 0.035"/>
      <geometry>
        <mesh filename="package://ros2_description/meshes/a1805/a1805_BaseEdge.stl" scale="0.001 0.001 0.001"/>
      </geometry>
      <material name="">
        <color rgba="0.2 0.2 0.2 1"/>
      </material>
    </visual>
  </link>
  <link name="link1">
    <inertial>
      <origin rpy="1.5707963267948966 0 0" xyz="0.062 0 0.35619999999999996"/>
      <mass value="10.2"/>
      <inertia ixx="0.003" ixy="0.0" ixz="0.0" iyy="0.003" iyz="0.0" izz="0.003"/>
    </inertial>
    <visual>
      <origin rpy="0 0 0" xyz="0.062 0 0.357"/>
      <geometry>
        <mesh filename="package://ros2_description/meshes/a1805/a1805_Link2.stl" scale="0.001 0.001 0.001"/>
      </geometry>
      <material name="">
        <color rgba="0.2 0.2 0.2 1"/>
      </material>
    </visual>
  </link>
  <link name="linkJ2">
    <visual>
      <origin rpy="1.5707963267948966 0 0" xyz="0 -0.006 0"/>
      <geometry>
        <cylinder length="0.15" radius="0.015"/>
      </geometry>
      <material name="orange"/>
    </visual>
    <inertial>
      <origin rpy="0 0 0" xyz="-0.062 0.1052 0.39430000000000004"/>
      <mass value="2.2"/>
      <inertia ixx="0.003" ixy="0.0" ixz="0.0" iyy="0.003" iyz="0.0" izz="0.003"/>
    </inertial>
  </link>
  <link name="link2">
    <inertial>
      <origin rpy="0 0 0" xyz="0 0 0.73961"/>
      <mass value="4.7"/>
      <inertia ixx="0.003" ixy="0.0" ixz="0.0" iyy="0.003" iyz="0.0" izz="0.003"/>
    </inertial>
    <visual>
      <origin rpy="0 0 0" xyz="0 0.00 0.17"/>
      <geometry>
        <mesh filename="package://ros2_description/meshes/a1805/a1805_Link3.stl" scale="0.001 0.001 0.001"/>
      </geometry>
      <material name="">
        <color rgba="0.2 0.2 0.2 1"/>
      </material>
    </visual>
  </link>
  <link name="link3">
    <inertial>
      <origin rpy="-1.5707963267948966 0 0" xyz="0.05 0 0.18289"/>
      <mass value="5.78"/>
      <inertia ixx="0.003" ixy="0.0" ixz="0.0" iyy="0.003" iyz="0.0" izz="0.003"/>
    </inertial>
    <visual>
      <origin rpy="0 0 0" xyz="0.05 0 0.1829"/>
      <geometry>
        <mesh filename="package://ros2_description/meshes/a1805/a1805_Link4.stl" scale="0.001 0.001 0.001"/>
      </geometry>
      <material name="">
        <color rgba="0.2 0.2 0.2 1"/>
      </material>
    </visual>
  </link>
  <link name="linkJ4">
    <visual>
      <origin rpy="1.5707963267948966 0 0" xyz="0 0.005 0"/>
      <geometry>
        <cylinder length="0.12" radius="0.015"/>
      </geometry>
      <material name="orange"/>
    </visual>
    <inertial>
      <origin rpy="0 0 0" xyz="-0.05 -0.0857 0.3737"/>
      <mass value="2.0"/>
      <inertia ixx="0.003" ixy="0.0" ixz="0.0" iyy="0.003" iyz="0.0" izz="0.003"/>
    </inertial>
  </link>
  <link name="link4">
    <inertial>
      <origin rpy="0 0 0" xyz="0 0 0.7776000000000001"/>
      <mass value="1.5"/>
      <inertia ixx="0.003" ixy="0.0" ixz="0.0" iyy="0.003" iyz="0.0" izz="0.003"/>
    </inertial>
    <visual>
      <origin rpy="3.1415926535 1.570796326795 0" xyz="0.126 0.0535 0.831"/>
      <geometry>
        <mesh filename="package://ros2_description/meshes/a1805/a1805_Link5.stl" scale="0.001 0.001 0.001"/>
      </geometry>
      <material name="">
        <color rgba="0.2 0.2 0.2 1"/>
      </material>
    </visual>
  </link>
  <link name="link5">
    <inertial>
      <origin rpy="1.5707963267948966 0 0" xyz="0 0 0.0999"/>
      <mass value="1.7"/>
      <inertia ixx="0.003" ixy="0.0" ixz="0.0" iyy="0.003" iyz="0.0" izz="0.003"/>
    </inertial>
    <visual>
      <origin rpy="0 0 0" xyz="0 0.002 0.1"/>
      <geometry>
        <mesh filename="package://ros2_description/meshes/a1805/a1805_Link6.stl" scale="0.001 0.001 0.001"/>
      </geometry>
      <material name="">
        <color rgba="0.2 0.2 0.2 1"/>
      </material>
    </visual>
  </link>
  <link name="linkJ6">
    <visual>
      <origin rpy="1.5707963267948966 0 0" xyz="0 0.01 0"/>
      <geometry>
        <cylinder length="0.105" radius="0.015"/>
      </geometry>
      <material name="orange"/>
    </visual>
    <inertial>
      <origin rpy="0 0 0" xyz="0 0 0"/>
      <mass value="0.0"/>
      <inertia ixx="0.003" ixy="0.0" ixz="0.0" iyy="0.003" iyz="0.0" izz="0.003"/>
    </inertial>
  </link>
  <link name="link6">
    <inertial>
      <origin rpy="0 0 0" xyz="0 0 0"/>
      <mass value="1.76"/>
      <inertia ixx="0.003" ixy="0.0" ixz="0.0" iyy="0.003" iyz="0.0" izz="0.003"/>
    </inertial>
    <visual>
      <origin rpy="0 0 0" xyz="0 0 0.002"/>
      <geometry>
        <mesh filename="package://ros2_description/meshes/a1805/a1805_Link7.stl" scale="0.001 0.001 0.001"/>
      </geometry>
      <material name="">
        <color rgba="0.2 0.2 0.2 1"/>
      </material>
    </visual>
  </link>
  <link name="end_effector">
    <visual>
      <origin rpy="0 0 0" xyz="0 0 -0.1051"/>
      <geometry>
        <mesh filename="package://ros2_description/meshes/a1805/a1805_ToolIO.stl" scale="0.001 0.001 0.001"/>
      </geometry>
      <material name="">
        <color rgba="0.8 0.8 0.8 1"/>
      </material>
    </visual>
    <inertial>
      <origin rpy="0 0 0" xyz="0 0 -0.021"/>
      <mass value="0.33"/>
      <inertia ixx="0.003" ixy="0.0" ixz="0.0" iyy="0.003" iyz="0.0" izz="0.003"/>
    </inertial>
  </link>
  <!-- joints -->
  <joint name="joint0" type="continuous">
    <parent link="base"/>
    <child link="link1"/>
    <origin rpy="0.0 -0.0 0.0" xyz="0 0 0.035"/>
    <axis xyz="0 0 1"/>
    <dynamics damping="1.0"/>
    <limit effort="500" lower="-6.283185307179586" upper="6.283185307179586" velocity="2.8361600344907854"/>
  </joint>
  <joint name="joint1" type="continuous">
    <parent link="link1"/>
    <child link="linkJ2"/>
    <origin rpy="0.0 0.0 0.0" xyz="0.062 0.0 0.3562"/>
    <axis xyz="0 1 0"/>
    <dynamics damping="1.0"/>
    <limit effort="500" lower="-1.2217304763960306" upper="3.141592653589793" velocity="2.8361600344907854"/>
  </joint>
  <joint name="jointPL2" type="fixed">
    <parent link="linkJ2"/>
    <child link="link2"/>
    <origin rpy="0.0 -0.0 0.0" xyz="-0.062 0.1052 0"/>
  </joint>
  <joint name="joint2" type="continuous">
    <parent link="link2"/>
    <child link="link3"/>
    <origin rpy="0 0 0" xyz="0 0 0.73961"/>
    <axis xyz="0 0 1"/>
    <dynamics damping="1.0"/>
    <limit effort="204" lower="-6.283185307179586" upper="6.283185307179586" velocity="3.9269908169872414"/>
  </joint>
  <joint name="joint3" type="continuous">
    <parent link="link3"/>
    <child link="linkJ4"/>
    <origin rpy="0.0 0.0 0.0" xyz="0.05 0.0 0.18289"/>
    <axis xyz="0 1 0"/>
    <dynamics damping="1.0"/>
    <limit effort="204" lower="-1.2217304763960306" upper="3.141592653589793" velocity="3.9269908169872414"/>
  </joint>
  <joint name="jointPL4" type="fixed">
    <parent link="linkJ4"/>
    <child link="link4"/>
    <origin rpy="0.0 -0.0 0.0" xyz="-0.05 -0.0857 0.0"/>
  </joint>
  <joint name="joint4" type="continuous">
    <parent link="link4"/>
    <child link="link5"/>
    <origin rpy="0 0 0" xyz="0 0 0.7776"/>
    <axis xyz="0 0 1"/>
    <dynamics damping="1.0"/>
    <limit effort="80" lower="-6.283185307179586" upper="6.283185307179586" velocity="3.9269908169872414"/>
  </joint>
  <joint name="joint5" type="continuous">
    <parent link="link5"/>
    <child link="linkJ6"/>
    <origin rpy="0.0 0.0 0.0" xyz="0.0 0 0.0999"/>
    <axis xyz="0 1 0"/>
    <dynamics damping="1.0"/>
    <limit effort="80" lower="-6.283185307179586" upper="6.283185307179586" velocity="3.9269908169872414"/>
  </joint>
  <joint name="jointPL6" type="fixed">
    <parent link="linkJ6"/>
    <child link="link6"/>
    <origin rpy="0.0 0.0 0.0" xyz="0.0 0.111 0"/>
  </joint>
  <joint name="joint6" type="continuous">
    <parent link="link6"/>
    <child link="end_effector"/>
    <origin rpy="0 0 0" xyz="0 0 0.108"/>
    <axis xyz="0 0 1"/>
    <dynamics damping="1.0"/>
    <limit effort="80" lower="-6.283185307179586" upper="6.283185307179586" velocity="3.9269908169872414"/>
  </joint>
</robot>
