<?xml version="1.0" ?>
<!-- =================================================================================== -->
<!-- |    This document was autogenerated by xacro from src/kr2_robot_S00V0000M1018.xacro | -->
<!-- |    EDITING THIS FILE BY HAND IS NOT RECOMMENDED                                 | -->
<!-- =================================================================================== -->
<robot features="TIO" mechanical-revision="1" model="a1018" model-revision="170524-0" name="kr2_robot_a1018">
<link name="world"/>
<joint name="world_joint" type="fixed">
  <parent link="world"/>
  <child link="base"/>
  <origin xyz="0 0 0" rpy="0 0 0"/>
</joint>
  <ruid>0</ruid>
  <!-- links -->
  <link name="base">
    <inertial>
      <origin rpy="0 0 0" xyz="0 0 0.1365"/>
      <mass value="8.2"/>
      <inertia ixx="0.003" ixy="0.0" ixz="0.0" iyy="0.003" iyz="0.0" izz="0.003"/>
    </inertial>
    <visual>
      <origin rpy="0 0 0" xyz="0 0 0"/>
      <geometry>
        <mesh filename="package://ros2_description/meshes/a1018/a1018_Base.stl" scale="0.001 0.001 0.001"/>
      </geometry>
      <material name="">
        <color rgba="0.2 0.2 0.2 1"/>
      </material>
    </visual>
    <collision>
      <origin xyz="0 0 0.05" rpy="0 0 0"/>
      <geometry>
        <cylinder length="0.1" radius="0.15"/>
      </geometry>
    </collision>
  </link>
  <link name="link1">
    <inertial>
      <origin rpy="1.5707963267948966 0 0" xyz="0.062 0 0.32210000000000005"/>
      <mass value="10.2"/>
      <inertia ixx="0.003" ixy="0.0" ixz="0.0" iyy="0.003" iyz="0.0" izz="0.003"/>
    </inertial>
    <visual>
      <origin rpy="0 0 0" xyz="0.062 0 0.322"/>
      <geometry>
        <mesh filename="package://ros2_description/meshes/a1018/a1018_Link2.stl" scale="0.001 0.001 0.001"/>
      </geometry>
      <material name="">
        <color rgba="0.2 0.2 0.2 1"/>
      </material>
    </visual>
    <collision>
      <origin rpy="0 0 0" xyz="0.062 0 0.30"/>
      <geometry>
        <cylinder length="0.20" radius="0.07"/>
      </geometry>
    </collision>
  </link>
  <link name="linkJ2">
    <visual>
      <origin rpy="1.5707963267948966 0 0" xyz="0 -0.006 0"/>
      <geometry>
        <cylinder length="0.15" radius="0.015"/>
      </geometry>
      <material name="orange"/>
    </visual>
    <inertial>
      <origin rpy="0 0 0" xyz="-0.062 0.1052 0.20495"/>
      <mass value="1.3"/>
      <inertia ixx="0.003" ixy="0.0" ixz="0.0" iyy="0.003" iyz="0.0" izz="0.003"/>
    </inertial>
  </link>
  <link name="link2">
    <inertial>
      <origin rpy="0 0 0" xyz="0 0 0.3396"/>
      <mass value="4.7"/>
      <inertia ixx="0.003" ixy="0.0" ixz="0.0" iyy="0.003" iyz="0.0" izz="0.003"/>
    </inertial>
    <visual>
      <origin rpy="0 0 0" xyz="0 0.00 0.17"/>
      <geometry>
        <mesh filename="package://ros2_description/meshes/a1018/a1018_Link3.stl" scale="0.001 0.001 0.001"/>
      </geometry>
      <material name="">
        <color rgba="0.2 0.2 0.2 1"/>
      </material>
    </visual>
    <collision>
      <origin rpy="0 0 0" xyz="0 0 0.25"/>
      <geometry>
        <cylinder length="0.22" radius="0.06"/>
      </geometry>
    </collision>
  </link>
  <link name="link3">
    <inertial>
      <origin rpy="-1.5707963267948966 0 0" xyz="0.05 0 0.1829"/>
      <mass value="5.78"/>
      <inertia ixx="0.003" ixy="0.0" ixz="0.0" iyy="0.003" iyz="0.0" izz="0.003"/>
    </inertial>
    <visual>
      <origin rpy="0 0 0" xyz="0.05 0 0.1829"/>
      <geometry>
        <mesh filename="package://ros2_description/meshes/a1018/a1018_Link4.stl" scale="0.001 0.001 0.001"/>
      </geometry>
      <material name="">
        <color rgba="0.2 0.2 0.2 1"/>
      </material>
    </visual>
    <collision>
      <origin rpy="0 0 0" xyz="0.05 0 0.1829"/>
      <geometry>
        <cylinder length="0.3" radius="0.06"/>
      </geometry>
    </collision>
  </link>
  <link name="linkJ4">
    <visual>
      <origin rpy="1.5707963267948966 0 0" xyz="0 0.005 0"/>
      <geometry>
        <cylinder length="0.12" radius="0.015"/>
      </geometry>
      <material name="orange"/>
    </visual>
    <collision>
      <origin rpy="1.5707963267948966 0 0" xyz="0 0.005 0"/>
      <geometry>
        <cylinder length="0.12" radius="0.015"/>
      </geometry>
    </collision>
    <inertial>
      <origin rpy="0 0 0" xyz="-0.05 -0.0857 0.1986"/>
      <mass value="0.75"/>
      <inertia ixx="0.003" ixy="0.0" ixz="0.0" iyy="0.003" iyz="0.0" izz="0.003"/>
    </inertial>
  </link>
  <link name="link4">
    <inertial>
      <origin rpy="0 0 0" xyz="0 0 0.3764"/>
      <mass value="1.5"/>
      <inertia ixx="0.003" ixy="0.0" ixz="0.0" iyy="0.003" iyz="0.0" izz="0.003"/>
    </inertial>
    <visual>
      <origin rpy="3.1415926535 1.570796326795 0" xyz="0.126 0.0535 0.431"/>
      <geometry>
        <mesh filename="package://ros2_description/meshes/a1018/a1018_Link5.stl" scale="0.001 0.001 0.001"/>
      </geometry>
      <material name="">
        <color rgba="0.2 0.2 0.2 1"/>
      </material>
    </visual>
    <collision>
    <origin rpy="0 0 0" xyz="0.126 0.0535 0.4"/>
    <geometry>
      <box size="0.1 0.1 0.15"/>
    </geometry>
  </collision>
  </link>
  <link name="link5">
    <inertial>
      <origin rpy="1.5707963267948966 0 0" xyz="0 0 0.1011"/>
      <mass value="1.7"/>
      <inertia ixx="0.003" ixy="0.0" ixz="0.0" iyy="0.003" iyz="0.0" izz="0.003"/>
    </inertial>
    <visual>
      <origin rpy="0 0 0" xyz="0 0.002 0.1011"/>
      <geometry>
        <mesh filename="package://ros2_description/meshes/a1018/a1018_Link6.stl" scale="0.001 0.001 0.001"/>
      </geometry>
      <material name="">
        <color rgba="0.2 0.2 0.2 1"/>
      </material>
    </visual>
    <collision>
      <origin rpy="0 0 0" xyz="0 0 0.1"/>
      <geometry>
        <cylinder length="0.15" radius="0.05"/>
      </geometry>
    </collision>
  </link>
  <link name="linkJ6">
    <visual>
      <origin rpy="1.5707963267948966 0 0" xyz="0 0.01 0"/>
      <geometry>
        <cylinder length="0.105" radius="0.015"/>
      </geometry>
      <material name="black"/>
    </visual>
    <collision>
      <origin rpy="1.5707963267948966 0 0" xyz="0 0.01 0"/>
      <geometry>
        <cylinder length="0.105" radius="0.015"/>
      </geometry>
      <material name="black"/>
    </collision>
    <inertial>
      <origin rpy="0 0 0" xyz="0 0 0"/>
      <mass value="0.0"/>
      <inertia ixx="0.003" ixy="0.0" ixz="0.0" iyy="0.003" iyz="0.0" izz="0.003"/>
    </inertial>
  </link>
  <link name="link6">
    <inertial>
      <origin rpy="0 0 0" xyz="0 0 0"/>
      <mass value="1.76"/>
      <inertia ixx="0.003" ixy="0.0" ixz="0.0" iyy="0.003" iyz="0.0" izz="0.003"/>
    </inertial>
    <visual>
      <origin rpy="0 0 0" xyz="0 0 0.002"/>
      <geometry>
        <mesh filename="package://ros2_description/meshes/a1018/a1018_Link7.stl" scale="0.001 0.001 0.001"/>
      </geometry>
      <material name="">
        <color rgba="0.2 0.2 0.2 1"/>
      </material>
    </visual>
    <collision>
    <origin rpy="0 0 0" xyz="0 0 0.01"/>
    <geometry>
      <cylinder length="0.04" radius="0.045"/>
    </geometry>
  </collision>
  </link>
  <link name="end_effector">
    <visual>
      <origin rpy="0 0 0" xyz="0 0 -0.1051"/>
      <geometry>
        <mesh filename="package://ros2_description/meshes/a1018/a1018_ToolIO.stl" scale="0.001 0.001 0.001"/>
      </geometry>
      <material name="">
        <color rgba="0.8 0.8 0.8 1"/>
      </material>
    </visual>
    <collision>
      <origin rpy="0 0 0" xyz="0 0 -0.05"/>
      <geometry>
        <cylinder length="0.1" radius="0.04"/>
      </geometry>
    </collision>
    <inertial>
      <origin rpy="0 0 0" xyz="0 0 -0.021"/>
      <mass value="0.33"/>
      <inertia ixx="0.003" ixy="0.0" ixz="0.0" iyy="0.003" iyz="0.0" izz="0.003"/>
    </inertial>
  </link>
  <!-- joints -->
  <joint name="joint0" type="continuous">
    <parent link="base"/>
    <child link="link1"/>
    <origin rpy="0.0 -0.0 0.0" xyz="0 0 0.035"/>
    <axis xyz="0 0 1"/>
    <dynamics damping="1.0"/>
    <limit effort="500" lower="-6.283185307179586" upper="6.283185307179586" velocity="2.8361600344907854"/>
  </joint>
  <joint name="joint1" type="continuous">
    <parent link="link1"/>
    <child link="linkJ2"/>
    <origin rpy="0.0 0.0 0.0" xyz="0.062 0.0 0.3222"/>
    <axis xyz="0 1 0"/>
    <dynamics damping="1.0"/>
    <limit effort="500" lower="-1.2217304763960306" upper="3.141592653589793" velocity="2.8361600344907854"/>
  </joint>
  <joint name="jointPL2" type="fixed">
    <parent link="linkJ2"/>
    <child link="link2"/>
    <origin rpy="0.0 -0.0 0.0" xyz="-0.062 0.1052 0"/>
  </joint>
  <joint name="joint2" type="continuous">
    <parent link="link2"/>
    <child link="link3"/>
    <origin rpy="0 0 0" xyz="0 0 0.3396"/>
    <axis xyz="0 0 1"/>
    <dynamics damping="1.0"/>
    <limit effort="204" lower="-6.283185307179586" upper="6.283185307179586" velocity="3.9269908169872414"/>
  </joint>
  <joint name="joint3" type="continuous">
    <parent link="link3"/>
    <child link="linkJ4"/>
    <origin rpy="0.0 0.0 0.0" xyz="0.05 0.0 0.1829"/>
    <axis xyz="0 1 0"/>
    <dynamics damping="1.0"/>
    <limit effort="204" lower="-1.2217304763960306" upper="3.141592653589793" velocity="3.9269908169872414"/>
  </joint>
  <joint name="jointPL4" type="fixed">
    <parent link="linkJ4"/>
    <child link="link4"/>
    <origin rpy="0.0 -0.0 0.0" xyz="-0.05 -0.0857 0.0"/>
  </joint>
  <joint name="joint4" type="continuous">
    <parent link="link4"/>
    <child link="link5"/>
    <origin rpy="0 0 0" xyz="0 0 0.3764"/>
    <axis xyz="0 0 1"/>
    <dynamics damping="1.0"/>
    <limit effort="80" lower="-6.283185307179586" upper="6.283185307179586" velocity="3.9269908169872414"/>
  </joint>
  <joint name="joint5" type="continuous">
    <parent link="link5"/>
    <child link="linkJ6"/>
    <origin rpy="0.0 0.0 0.0" xyz="0.0 0 0.1011"/>
    <axis xyz="0 1 0"/>
    <dynamics damping="1.0"/>
    <limit effort="80" lower="-6.283185307179586" upper="6.283185307179586" velocity="3.9269908169872414"/>
  </joint>
  <joint name="jointPL6" type="fixed">
    <parent link="linkJ6"/>
    <child link="link6"/>
    <origin rpy="0.0 0.0 0.0" xyz="0.0 0.111 0"/>
  </joint>
  <joint name="joint6" type="continuous">
    <parent link="link6"/>
    <child link="end_effector"/>
    <origin rpy="0 0 0" xyz="0 0 0.108"/>
    <axis xyz="0 0 1"/>
    <dynamics damping="1.0"/>
    <limit effort="80" lower="-6.283185307179586" upper="6.283185307179586" velocity="3.9269908169872414"/>
  </joint>
  
 <ros2_control name="GazeboSystem" type="system">
  <hardware>
    <plugin>gz_ros2_control/GazeboSimSystem</plugin>
  </hardware>
  <joint name="joint0">
    <command_interface name="position"/>
    <state_interface name="position"><param name="initial_value">0.0</param></state_interface>
    <state_interface name="velocity"/>
  </joint>
  <joint name="joint1">
    <command_interface name="position"/>
    <state_interface name="position"><param name="initial_value">0.0</param></state_interface>
    <state_interface name="velocity"/>
  </joint>
  <joint name="joint2">
    <command_interface name="position"/>
    <state_interface name="position"><param name="initial_value">0.0</param></state_interface>
    <state_interface name="velocity"/>
  </joint>
  <joint name="joint3">
    <command_interface name="position"/>
    <state_interface name="position"><param name="initial_value">0.0</param></state_interface>
    <state_interface name="velocity"/>
  </joint>
  <joint name="joint4">
    <command_interface name="position"/>
    <state_interface name="position"><param name="initial_value">0.0</param></state_interface>
    <state_interface name="velocity"/>
  </joint>
  <joint name="joint5">
    <command_interface name="position"/>
    <state_interface name="position"><param name="initial_value">0.0</param></state_interface>
    <state_interface name="velocity"/>
  </joint>
  <joint name="joint6">
    <command_interface name="position"/>
    <state_interface name="position"><param name="initial_value">0.0</param></state_interface>
    <state_interface name="velocity"/>
  </joint>
</ros2_control>
  
<gazebo>
  <plugin filename="gz_ros2_control-system" name="gz_ros2_control::GazeboSimROS2ControlPlugin">
  <parameters>/home/raphi/ros2tutorial_ws/install/ros2_description/share/ros2_description/launch/robot_controller_gazebo.yaml</parameters>
</plugin>
</gazebo>

<gazebo reference="link1">
    <self_collide>false</self_collide>
  </gazebo>

<gazebo reference="link2">
    <self_collide>false</self_collide>
  </gazebo>

  <gazebo reference="link3">
    <self_collide>false</self_collide>
  </gazebo>

  <gazebo reference="base">
    <visual>
      <material>
        <ambient>0.2 0.2 0.2 1.0</ambient>
        <diffuse>0.2 0.2 0.2 1.0</diffuse>
        <specular>0.1 0.1 0.1 1.0</specular>
      </material>
    </visual>
  </gazebo>
</robot>
