<?xml version="1.0" ?>
<!-- =================================================================================== -->
<!-- |    This document was autogenerated by xacro from src/kr2_robot_S00V0000M1205.xacro | -->
<!-- |    EDITING THIS FILE BY HAND IS NOT RECOMMENDED                                 | -->
<!-- =================================================================================== -->
<robot features="TIO" mechanical-revision="5" model="a1205" model-revision="030424-0" name="kr2_robot_a1205">
  <ruid>0</ruid>
  <!-- links -->
  <link name="base">
    <visual>
      <origin rpy="0 0 0" xyz="0 0 0"/>
      <geometry>
        <mesh filename="package://ros2_description/meshes/a1205/a1205_Base.stl" scale="0.001 0.001 0.001"/>
      </geometry>
      <material name="">
        <color rgba="0.2 0.2 0.2 1"/>
      </material>
    </visual>
    <inertial>
      <origin rpy="0 0 0" xyz="0 0 0"/>
      <mass value="0.6"/>
      <inertia ixx="0.003" ixy="0.0" ixz="0.0" iyy="0.003" iyz="0.0" izz="0.003"/>
    </inertial>
  </link>
  <link name="link1">
    <visual>
      <origin rpy="0 0 0" xyz="0.05 0 0.2736"/>
      <geometry>
        <mesh filename="package://ros2_description/meshes/a1205/a1205_Link2.stl" scale="0.001 0.001 0.001"/>
      </geometry>
      <material name="">
        <color rgba="0.2 0.2 0.2 1"/>
      </material>
    </visual>
    <inertial>
      <origin rpy="0 0 0" xyz="0 0 0.13684999999999997"/>
      <mass value="6.0"/>
      <inertia ixx="0.003" ixy="0.0" ixz="0.0" iyy="0.003" iyz="0.0" izz="0.003"/>
    </inertial>
  </link>
  <link name="linkJ2">
    <visual>
      <origin rpy="1.5707963267948966 0 0" xyz="0 -0.01 0"/>
      <geometry>
        <cylinder length="0.15" radius="0.015"/>
      </geometry>
      <material name="orange"/>
    </visual>
    <collision>
      <origin rpy="1.5707963267948966 0 0" xyz="0 -0.01 0"/>
      <geometry>
        <cylinder length="0.15" radius="0.015"/>
      </geometry>
    </collision>
    <inertial>
      <origin rpy="0 0 0" xyz="0 0 0"/>
      <mass value="6.1"/>
      <inertia ixx="0.003" ixy="0.0" ixz="0.0" iyy="0.003" iyz="0.0" izz="0.003"/>
    </inertial>
  </link>
  <link name="link2">
    <visual>
      <origin rpy="0 0 0" xyz="0.05 -0.00 0.00"/>
      <geometry>
        <mesh filename="package://ros2_description/meshes/a1205/a1205_Link3.stl" scale="0.001 0.001 0.001"/>
      </geometry>
      <material name="">
        <color rgba="0.2 0.2 0.2 1"/>
      </material>
    </visual>
    <inertial>
      <origin rpy="0 0 0" xyz="0 0 0.17500000000000002"/>
      <mass value="0.69"/>
      <inertia ixx="0.003" ixy="0.0" ixz="0.0" iyy="0.003" iyz="0.0" izz="0.003"/>
    </inertial>
  </link>
  <link name="link3">
    <visual>
      <origin rpy="0 0 0" xyz="0.041 0  0.3429"/>
      <geometry>
        <mesh filename="package://ros2_description/meshes/a1205/a1205_Link4.stl" scale="0.001 0.001 0.001"/>
      </geometry>
      <material name="">
        <color rgba="0.2 0.2 0.2 1"/>
      </material>
    </visual>
    <inertial>
      <origin rpy="0 0 0" xyz="0 0 0"/>
      <mass value="2.9"/>
      <inertia ixx="0.003" ixy="0.0" ixz="0.0" iyy="0.003" iyz="0.0" izz="0.003"/>
    </inertial>
  </link>
  <link name="linkJ4">
    <visual>
      <origin rpy="1.5707963267948966 0 0" xyz="0 0.013000000000000001 0"/>
      <geometry>
        <cylinder length="0.129" radius="0.015"/>
      </geometry>
      <material name="orange"/>
    </visual>
    <collision>
      <origin rpy="1.5707963267948966 0 0" xyz="0 0.013000000000000001 0"/>
      <geometry>
        <cylinder length="0.129" radius="0.015"/>
      </geometry>
    </collision>
    <inertial>
      <origin rpy="0 0 0" xyz="0 0.006500000000000001 0"/>
      <mass value="3.8"/>
      <inertia ixx="0.003" ixy="0.0" ixz="0.0" iyy="0.003" iyz="0.0" izz="0.003"/>
    </inertial>
  </link>
  <link name="link4">
    <visual>
      <origin rpy="0 0 0" xyz="0.041 0.0 0"/>
      <geometry>
        <mesh filename="package://ros2_description/meshes/a1205/a1205_Link5.stl" scale="0.001 0.001 0.001"/>
      </geometry>
      <material name="">
        <color rgba="0.2 0.2 0.2 1"/>
      </material>
    </visual>
    <inertial>
      <origin rpy="0 0 0" xyz="0 0 0.168"/>
      <mass value="0.46"/>
      <inertia ixx="0.003" ixy="0.0" ixz="0.0" iyy="0.003" iyz="0.0" izz="0.003"/>
    </inertial>
  </link>
  <link name="link5">
    <visual>
      <origin rpy="0 0 0" xyz="0.001 0.002 0.3035"/>
      <geometry>
        <mesh filename="package://ros2_description/meshes/a1205/a1205_Link6.stl" scale="0.001 0.001 0.001"/>
      </geometry>
      <material name="">
        <color rgba="0.2 0.2 0.2 1"/>
      </material>
    </visual>
    <inertial>
      <origin rpy="0 0 0" xyz="0 0 0"/>
      <mass value="1.7"/>
      <inertia ixx="0.003" ixy="0.0" ixz="0.0" iyy="0.003" iyz="0.0" izz="0.003"/>
    </inertial>
  </link>
  <link name="linkJ6">
    <visual>
      <origin rpy="1.5707963267948966 0 0" xyz="0 0.01 0"/>
      <geometry>
        <cylinder length="0.105" radius="0.015"/>
      </geometry>
      <material name="orange"/>
    </visual>
    <collision>
      <origin rpy="1.5707963267948966 0 0" xyz="0 0.01 0"/>
      <geometry>
        <cylinder length="0.105" radius="0.015"/>
      </geometry>
    </collision>
    <inertial>
      <origin rpy="0 0 0" xyz="0 0.004 0"/>
      <mass value="1.8"/>
      <inertia ixx="0.003" ixy="0.0" ixz="0.0" iyy="0.003" iyz="0.0" izz="0.003"/>
    </inertial>
  </link>
  <link name="link6">
    <visual>
      <origin rpy="0 0 0" xyz="0.001 0.00 0.002"/>
      <geometry>
        <mesh filename="package://ros2_description/meshes/a1205/a1205_Link7.stl" scale="0.001 0.001 0.001"/>
      </geometry>
      <material name="">
        <color rgba="0.2 0.2 0.2 1"/>
      </material>
    </visual>
    <inertial>
      <origin rpy="0 0 0" xyz="0 0 0.004"/>
      <mass value="1.8"/>
      <inertia ixx="0.003" ixy="0.0" ixz="0.0" iyy="0.003" iyz="0.0" izz="0.003"/>
    </inertial>
  </link>
  <link name="end_effector">
    <visual>
      <origin rpy="0 0 0" xyz="0.00 0 -0.105"/>
      <geometry>
        <mesh filename="package://ros2_description/meshes/a1205/a1205_ToolIO.stl" scale="0.001 0.001 0.001"/>
      </geometry>
      <material name="">
        <color rgba="0.8 0.8 0.8 1"/>
      </material>
    </visual>
    <inertial>
      <origin rpy="0 0 0" xyz="0 0 -0.0197"/>
      <mass value="0.56"/>
      <inertia ixx="0.003" ixy="0.0" ixz="0.0" iyy="0.003" iyz="0.0" izz="0.003"/>
    </inertial>
  </link>
  <!-- joints -->
  <joint name="joint0" type="continuous">
    <parent link="base"/>
    <child link="link1"/>
    <origin rpy="0.0 -0.0 0.0" xyz="0 0 0.035"/>
    <axis xyz="0 0 1"/>
    <dynamics damping="0.0"/>
    <limit effort="204" lower="-6.283185307179586" upper="6.283185307179586" velocity="3.9269908169872414"/>
  </joint>
  <joint name="joint1" type="continuous">
    <parent link="link1"/>
    <child link="linkJ2"/>
    <origin rpy="0.0 0.0 0.0" xyz="0.05 0.0 0.2737"/>
    <axis xyz="0 1 0"/>
    <dynamics damping="0.0"/>
    <limit effort="204" lower="-1.2217304763960306" upper="3.141592653589793" velocity="3.9269908169872414"/>
  </joint>
  <joint name="jointPL2" type="fixed">
    <parent link="linkJ2"/>
    <child link="link2"/>
    <origin rpy="0.0 -0.0 0.0" xyz="-0.05 -0.0857 0"/>
  </joint>
  <joint name="joint2" type="continuous">
    <parent link="link2"/>
    <child link="link3"/>
    <origin rpy="0 0 0" xyz="0 0 0.274"/>
    <axis xyz="0 0 1"/>
    <dynamics damping="0.0"/>
    <limit effort="85" lower="-6.283185307179586" upper="6.283185307179586" velocity="3.9269908169872414"/>
  </joint>
  <joint name="joint3" type="continuous">
    <parent link="link3"/>
    <child link="linkJ4"/>
    <origin rpy="0.0 0.0 0.0" xyz="0.04 0.0 0.3429"/>
    <axis xyz="0 1 0"/>
    <dynamics damping="0.0"/>
    <limit effort="85" lower="-1.2217304763960306" upper="3.141592653589793" velocity="3.9269908169872414"/>
  </joint>
  <joint name="jointPL4" type="fixed">
    <parent link="linkJ4"/>
    <child link="link4"/>
    <origin rpy="0.0 -0.0 0.0" xyz="-0.04 0.08405 0.0"/>
  </joint>
  <joint name="joint4" type="continuous">
    <parent link="link4"/>
    <child link="link5"/>
    <origin rpy="0 0 0" xyz="0 0 0.271"/>
    <axis xyz="0 0 1"/>
    <dynamics damping="0.0"/>
    <limit effort="51" lower="-6.283185307179586" upper="6.283185307179586" velocity="3.9269908169872414"/>
  </joint>
  <joint name="joint5" type="continuous">
    <parent link="link5"/>
    <child link="linkJ6"/>
    <origin rpy="0.0 0.0 0.0" xyz="0.0 0 0.3035"/>
    <axis xyz="0 1 0"/>
    <dynamics damping="0.0"/>
    <limit effort="51" lower="-6.283185307179586" upper="6.283185307179586" velocity="3.9269908169872414"/>
  </joint>
  <joint name="jointPL6" type="fixed">
    <parent link="linkJ6"/>
    <child link="link6"/>
    <origin rpy="0.0 0.0 0.0" xyz="0.0 0.111 0"/>
  </joint>
  <joint name="joint6" type="continuous">
    <parent link="link6"/>
    <child link="end_effector"/>
    <origin rpy="0 0 0" xyz="0 0 0.108"/>
    <axis xyz="0 0 1"/>
    <dynamics damping="0.0"/>
    <limit effort="51" lower="-6.283185307179586" upper="6.283185307179586" velocity="3.9269908169872414"/>
  </joint>
</robot>
